Workbook

Sheet 📊 Dashboard
B1: ✦ FINANCIAL FREEDOM CALCULATOR
B4: Your path to financial independence — update Profile, Inputs, Investments & Life Events sheets
B6: Freedom Number | C6: Current Net Worth | D6: Years to Freedom | E6: Freedom Age | F6: Monthly Surplus | G6: Progress %
B7: =Profile!C30 -> 74171860 | C7: =Profile!C33 -> 2860000 | D7: =Profile!C35 -> 33 | E7: =Profile!C36 -> 63 | F7: ='Income & Spend'!G5 -> -41540.687 | G7: =IF(Profile!C30>0,MIN(1,Investments!B38/Profile!C30),0) -> 0.010246474
B8: Target Corpus | C8: Assets − Liabilities | D8: At current savings rate | E8: When you reach corpus | F8: After all expenses & SIPs | G8: Corpus achieved so far
B10: 💰 MONTHLY CASH FLOW | E10: 🏦 BALANCE SHEET
B11: Total Monthly Income | C11: ='Income & Spend'!G3 -> TOTAL | E11: Investment Portfolio | F11: =Investments!B38 -> 760000
B12: Total Monthly Expenses | C12: ='Income & Spend'!G4 -> Surplus → Dashboard | E12: Property Value | F12: =IF('Assets & Liabilities'!C4="Own",'Assets & Liabilities'!C6,0) -> 8000000
B13: Total EMIs | C13: ='Assets & Liabilities'!B42 -> 67540.687 | E13: Other Assets | F13: ='Assets & Liabilities'!B20 -> 1000000
B14: Total Monthly SIPs | C14: =Investments!B36 -> 28000 | E14: Total Liabilities | F14: ='Assets & Liabilities'!B43 -> 6900000
B15: Net Monthly Surplus | C15: ='Income & Spend'!G5 -> -41540.687 | E15: Net Worth | F15: =Profile!C33 -> 2860000
B17: 🌅 POST-FREEDOM CASHFLOW | E17: 🎯 LIFE EVENTS IMPACT
B18: Monthly Expenses (post-FI) | C18: ='Income & Spend'!H4 -> 46500 | E18: Marriage Cost (inflated) | F18: ='Life Events'!E4 -> Today Cost (₹)
B19: Passive / Part-time Income | C19: ='Income & Spend'!G12 -> 0 | E19: Kids Education (total) | F19: ='Life Events'!E15 -> 7563998.8
B20: Net Monthly Withdrawal | C20: =MAX(0,'📊 Dashboard'!C18-'📊 Dashboard'!C19) -> 46500 | E20: Custom Goals (total) | F20: ='Life Events'!E28 -> 20182921
B21: Annual Withdrawal Needed | C21: ='📊 Dashboard'!C20*12 -> 558000 | E21: Total Life Event Impact | F21: ='Life Events'!E30 -> 29432320
B22: Safe Corpus (SWR based) | C22: =Profile!C30 -> 74171860 | E22: Adj. Freedom Number | F22: =Profile!B31 -> Adjusted Freedom Number
B24: 📌 HOW TO USE THIS CALCULATOR
B25: 1️⃣ Profile Sheet | C25: Set your age, target freedom age, currency, inflation & SWR rate
B26: 2️⃣ Income & Spend | C26: Enter current & post-freedom monthly income and expenses
B27: 3️⃣ Assets & Liabilities | C27: Add your home (own/rent), other assets, loans and EMIs
B28: 4️⃣ Investments | C28: Add each investment with current value, monthly SIP and XIRR
B29: 5️⃣ Life Events | C29: Plan marriage, children, education and custom goals
B30: 6️⃣ Projections | C30: View year-by-year wealth chart and corpus projection
B33: 🎨 COLOR KEY
B34: Blue text | C34: User input / hardcoded values — change these
B35: Black text | C35: Calculated formulas — do not edit
B36: Green text | C36: Cross-sheet links
B37: Yellow background | C37: Key assumptions to review

Sheet Profile
B1: 👤 PROFILE & ASSUMPTIONS
B3: PERSONAL DETAILS
B4: Current Age (years) | C4: 30 | D4: Enter your age today
B5: Target Freedom Age | C5: 50 | D5: Age at which you want to retire
B6: Life Expectancy | C6: 85 | D6: Used for corpus duration check
B7: Annual Inflation Rate | C7: 0.06 | D7: Expected annual inflation (e.g. 0.06 = 6%)
B8: Safe Withdrawal Rate (SWR) | C8: 0.04 | D8: 4% = classic FIRE rule; 3.5% for early retirement
B9: Currency Symbol | C9: ₹ | D9: ₹ for INR; $ for USD; € for EUR etc.
B11: CURRENT LOCATION | D11: POST-FREEDOM LOCATION
B12: Country (Current) | C12: India | D12: Country (Post-Freedom) | E12: India
B13: City (Current) | C13: Bangalore | D13: City (Post-Freedom) | E13: Goa
B15: 📐 DERIVED CALCULATIONS
B16: Years to Freedom (target) | C16: =C5-C4 -> 20
B17: Years in Retirement | C17: =C6-C5 -> 35
B18: Inflation Multiplier @ Target | C18: =POWER(1+C7,C16) -> 3.2071355
B20: 🎯 FREEDOM NUMBER CALCULATION
B21: Post-FI Monthly Expenses | C21: ='Income & Spend'!H4 -> 46500
B22: Post-FI Passive Income | C22: ='Income & Spend'!H12 -> 0
B23: Net Monthly Withdrawal | C23: =MAX(0,C21-C22) -> 46500
B24: Annual Withdrawal Needed | C24: =C23*12 -> 558000
B25: Inflated Annual Withdrawal | C25: =C24*C18 -> 1789581.6
B26: Base Freedom Number | C26: =C25/C8 -> 44739540
B27: Life Events Total Impact
B28: Total Life Events Cost (inflated) | C28: ='Life Events'!E30 -> 29432320
B29: ✦ ADJUSTED FREEDOM NUMBER
B30: FREEDOM NUMBER (with Life Events) | C30: =C26+C28 -> 74171860 | D30: ← Target corpus to retire
B31: Adjusted Freedom Number | C31: =C30 -> 74171860
B32: NET WORTH ►
B33: Current Net Worth | C33: =Investments!B38+IF('Assets & Liabilities'!C4="Own",'Assets & Liabilities'!C6,0)+'Assets & Liabilities'!B20-'Assets & Liabilities'!B43 -> 2860000
B34: ⏱ TIME TO FREEDOM
B35: Approx Years to Hit Corpus | C35: =Projections!B5 -> 33
B36: Freedom Age (approx) | C36: =IFERROR(Profile!C4+Profile!C35,"Beyond age "&Profile!C6) -> 63

Sheet Income & Spend
B1: 💰 INCOME & SPENDING
B3: CURRENT INCOME | E3: POST-FREEDOM INCOME | G3: TOTAL | H3: =C8 -> 100000
B4: Monthly Take-Home Salary | C4: 100000 | E4: Part-time / Passive Income | F4: 0 | G4: Surplus → Dashboard | H4: =F20 -> 46500
B5: Spouse Monthly Income | C5: 0 | E5: Rental Income | F5: 0 | G5: =C28 -> -41540.687
B6: Other Income (Rent, Freelance) | C6: 0 | E6: Other Post-FI Income | F6: 0
B7: Annual Bonus ÷ 12 | C7: 0 | E7: Pension / Annuity | F7: 0
B8: Total Current Income | C8: =SUM(C4:C7) -> 100000 | E8: Total Post-FI Income | F8: =SUM(F4:F7) -> 0
B10: CURRENT MONTHLY EXPENSES | E10: POST-FREEDOM MONTHLY EXPENSES
B11: Category | C11: Amount (₹) | E11: Category | F11: Amount (₹) | H11: Diff
B12: Housing (Rent/EMI) | C12: 20000 | E12: Housing | F12: 15000 | G12: =F8 -> 0 | H12: =F8 -> 0
B13: Food & Groceries | C13: 10000 | E13: Food & Groceries | F13: 10000 | H13: =F13-C13 -> 0
B14: Transport | C14: 5000 | E14: Transport | F14: 3000 | H14: =F14-C14 -> -2000
B15: Utilities & Bills | C15: 3000 | E15: Utilities & Bills | F15: 2500 | H15: =F15-C15 -> -500
B16: Health & Insurance | C16: 3000 | E16: Health & Insurance | F16: 5000 | H16: =F16-C16 -> 2000
B17: Entertainment & Lifestyle | C17: 5000 | E17: Entertainment | F17: 8000 | H17: =F17-C17 -> 3000
B18: Children & Education | C18: 0 | E18: Miscellaneous | F18: 3000 | H18: =F18-C18 -> 3000
B19: Other | C19: 0 | E19: Other | F19: 0 | H19: =F19-C19 -> 0
B20: TOTAL EXPENSES | C20: =SUM(C12:C19) -> 46000 | E20: TOTAL POST-FI EXPENSES | F20: =SUM(F12:F19) -> 46500
B24: Total Income | C24: =C8 -> 100000 | E24: Post-FI (₹/mo) | F24: =F8 -> 0
B25: Total Expenses | C25: =C20 -> 46000 | F25: =F20 -> 46500
B26: EMIs | C26: ='Assets & Liabilities'!B42 -> 67540.687 | F26: =0 -> 0
B27: SIPs | C27: =Investments!B36 -> 28000 | F27: =0 -> 0
B28: NET SURPLUS | C28: =C24-C25-C26-C27 -> -41540.687 | F28: =F24-F25 -> -46500

Sheet Assets & Liabilities
B1: 🏠 ASSETS & LIABILITIES
B3: 🏘️ HOUSING — OWN vs RENT
B4: Housing Choice (Own / Rent) | C4: Own | D4: Enter 'Own' or 'Rent'
B5: IF OWN — Home Details
B6: Property Market Value | C6: 8000000
B7: Home Loan Outstanding Balance | C7: 6400000
B8: =IF(C4="Own",C6-C7,0) -> 1600000 | C8: 0.085
B9: Remaining Tenure (years) | C9: 20
B10: Property Appreciation (%/yr) | C10: 0.05
B11: Computed Monthly EMI | C11: =IF(C4="Own",IFERROR(C7*(C8/12)*POWER(1+C8/12,C9*12)/(POWER(1+C8/12,C9*12)-1),0),0) -> 55540.687
B12: Net Property Value (Equity) | C12: =IF(C4="Own",C6-C7,0) -> 1600000
B13: IF RENT
B14: Monthly Rent | C14: 20000
B15: Annual Rent Increase (%) | C15: 0.05
B17: 💎 OTHER ASSETS
B18: Asset Name | C18: Current Value (₹) | D18: Type | E18: Notes
B19: Car / Vehicle | C19: 500000 | D19: Vehicle | E19: Depreciating asset
B20: =C25 -> 1000000 | C20: 200000 | D20: Gold | E20: Include ETF/SGB value
B21: Land / Plot | C21: 0 | D21: Real Estate | E21: Market value today
B22: PF / Gratuity | C22: 300000 | D22: Retirement Fund | E22: Current PF balance
B23: Other Asset 1 | C23: 0 | D23: Other
B24: Other Asset 2 | C24: 0 | D24: Other
B25: TOTAL OTHER ASSETS | C25: =SUM(C19:C24) -> 1000000
B27: 🔴 LOANS & LIABILITIES (excl. Home Loan)
B28: Loan Name | C28: Outstanding Balance | D28: Monthly EMI | E28: Interest Rate | F28: Notes
B29: Car Loan | C29: 500000 | D29: 12000 | E29: 0.09 | F29: 9% p.a.
B30: Personal Loan | C30: 0 | D30: 0 | E30: 0.12
B31: Education Loan | C31: 0 | D31: 0 | E31: 0.085
B32: Credit Card | C32: 0 | D32: 0 | E32: 0.36 | F32: Revolving balance
B33: Other Loan 1 | C33: 0 | D33: 0 | E33: 0.1
B34: Other Loan 2 | C34: 0 | D34: 0 | E34: 0.1
B35: TOTAL LIABILITIES (excl. home) | C35: =SUM(C29:C34) -> 500000
B36: TOTAL EMIs (excl. home) | C36: =SUM(D29:D34) -> 12000
B42: =C36+C11 -> 67540.687
B43: =C35+IF(C4="Own",C7,0) -> 6900000

Sheet Investments
B1: 📈 INVESTMENT PORTFOLIO
B3: INVESTMENT PORTFOLIO — XIRR / EXPECTED RETURN
B4: Investment Type | C4: Current Value (₹) | D4: Monthly SIP (₹) | E4: XIRR / Rate % | F4: Projected 10Y Value (₹) | G4: Notes
B5: Equity Mutual Fund | C5: 200000 | D5: 10000 | E5: 0.12 | F5: =IFERROR(C5*POWER(1+E5,10)+IF(D5>0,D5*(POWER(1+E5/12,10*12)-1)/(E5/12),0),0) -> 2921556.5 | G5: Diversified / Flexi Cap
B6: Index Fund / ETF | C6: 100000 | D6: 5000 | E6: 0.11 | F6: =IFERROR(C6*POWER(1+E6,10)+IF(D6>0,D6*(POWER(1+E6/12,10*12)-1)/(E6/12),0),0) -> 1368932.8 | G6: Nifty 50 / S&P 500
B7: Debt Mutual Fund | C7: 50000 | D7: 2000 | E7: 0.07 | F7: =IFERROR(C7*POWER(1+E7,10)+IF(D7>0,D7*(POWER(1+E7/12,10*12)-1)/(E7/12),0),0) -> 444527.18 | G7: Short / Medium duration
B8: Gold (ETF / SGB) | C8: 80000 | D8: 1000 | E8: 0.08 | F8: =IFERROR(C8*POWER(1+E8,10)+IF(D8>0,D8*(POWER(1+E8/12,10*12)-1)/(E8/12),0),0) -> 355660.03 | G8: Sovereign Gold Bond
B9: Fixed Deposit | C9: 100000 | D9: 0 | E9: 0.07 | F9: =IFERROR(C9*POWER(1+E9,10)+IF(D9>0,D9*(POWER(1+E9/12,10*12)-1)/(E9/12),0),0) -> 196715.14 | G9: Bank FD
B10: PPF | C10: 150000 | D10: 5000 | E10: 0.071 | F10: =IFERROR(C10*POWER(1+E10,10)+IF(D10>0,D10*(POWER(1+E10/12,10*12)-1)/(E10/12),0),0) -> 1168045.1 | G10: Public Provident Fund
B11: NPS | C11: 50000 | D11: 3000 | E11: 0.1 | F11: =IFERROR(C11*POWER(1+E11,10)+IF(D11>0,D11*(POWER(1+E11/12,10*12)-1)/(E11/12),0),0) -> 744222.06 | G11: National Pension System
B12: US Stocks / ETF | C12: 30000 | D12: 2000 | E12: 0.11 | F12: =IFERROR(C12*POWER(1+E12,10)+IF(D12>0,D12*(POWER(1+E12/12,10*12)-1)/(E12/12),0),0) -> 519178.91 | G12: S&P 500 index fund
B13: Direct Stocks | C13: 0 | D13: 0 | E13: 0.13 | F13: =IFERROR(C13*POWER(1+E13,10)+IF(D13>0,D13*(POWER(1+E13/12,10*12)-1)/(E13/12),0),0) -> 0
B14: Real Estate (REITs) | C14: 0 | D14: 0 | E14: 0.09 | F14: =IFERROR(C14*POWER(1+E14,10)+IF(D14>0,D14*(POWER(1+E14/12,10*12)-1)/(E14/12),0),0) -> 0
B15: Crypto | C15: 0 | D15: 0 | E15: 0.18 | F15: =IFERROR(C15*POWER(1+E15,10)+IF(D15>0,D15*(POWER(1+E15/12,10*12)-1)/(E15/12),0),0) -> 0 | G15: High risk
B16: Other Investments | C16: 0 | D16: 0 | E16: 0.08 | F16: =IFERROR(C16*POWER(1+E16,10)+IF(D16>0,D16*(POWER(1+E16/12,10*12)-1)/(E16/12),0),0) -> 0
B17: TOTAL PORTFOLIO | C17: =SUM(C5:C16) -> 760000 | D17: =SUM(D5:D16) -> 28000 | F17: =SUM(F5:F16) -> 7718837.7
B18: Weighted Portfolio XIRR | E18: =IFERROR(SUMPRODUCT(C5:C16,E5:E16)/SUMIF(C5:C16,">0",C5:C16),0.1) -> 0.093223684
B21: 📊 XIRR REFERENCE GUIDE (Historical / Expected)
B22: Asset Class | C22: Low | D22: Mid | E22: High | F22: Risk | G22: Notes
B23: Equity Mutual Fund | C23: 10% | D23: 12% | E23: 15% | F23: High | G23: 10Y+ horizon
B24: Index Fund / ETF | C24: 9% | D24: 11% | E24: 12% | F24: Medium-High | G24: Low cost, market returns
B25: NPS (Equity) | C25: 8% | D25: 10% | E25: 11% | F25: Medium | G25: Long lock-in
B26: Gold (ETF/SGB) | C26: 6% | D26: 8% | E26: 10% | F26: Medium | G26: Hedge against inflation
B27: PPF | C27: 7.1% | D27: 7.1% | E27: 7.1% | F27: Low | G27: Tax-free, guaranteed
B28: Fixed Deposit | C28: 6.5% | D28: 7% | E28: 7.5% | F28: Very Low | G28: Taxable interest
B29: Debt Mutual Fund | C29: 6% | D29: 7% | E29: 8% | F29: Low-Medium | G29: Better than FD post-tax
B30: US ETF (S&P 500) | C30: 9% | D30: 11% | E30: 13% | F30: Medium-High | G30: Currency risk
B31: Direct Stocks | C31: 8% | D31: 13% | E31: 20% | F31: Very High | G31: Stock picking risk
B32: Crypto | C32: 0% | D32: 18% | E32: 40% | F32: Extreme | G32: Speculative only
B36: =D17 -> 28000
B38: =C17 -> 760000

Sheet Life Events
B1: 🎯 LIFE EVENTS & GOALS
B3: 💑 MARRIAGE
C4: Marry? (Yes/No) | D4: Your Age | E4: Today Cost (₹) | F4: Inflated Cost (₹)
B5: Marriage | C5: Yes | D5: 32 | E5: 1500000 | F5: =IF(LOWER(C5)="yes",E5*POWER(1+Profile!C7,MAX(0,D5-Profile!C4)),0) -> 1685400
B6: 👶 CHILDREN
B7: Child | C7: Your Age at Birth | D7: Monthly Cost | E7: Education Cost (today ₹) | F7: Inflated Edu. Cost
B8: Child 1 | C8: 31 | D8: 15000 | E8: 2500000 | F8: =IF(C8>0,E8*POWER(1+Profile!C7,MAX(0,C8+18-Profile!C4)),0) -> 7563998.8
B9: Education Inflation Override (%) | C9: 0 | D9: 0 | E9: 0 | F9: =IF(C9>0,E9*POWER(1+Profile!C7,MAX(0,C9+18-Profile!C4)),0) -> 0
B10: Education Inflation (%) | C10: 0.1 | D10: 0 | E10: 0 | F10: =IF(C10>0,E10*POWER(1+Profile!C7,MAX(0,C10+18-Profile!C4)),0) -> 0
B11: TOTAL CHILDREN EDUCATION | E11: =SUM(F8:F10) -> 7563998.8
B13: ✈️ CUSTOM LIFE GOALS
B14: Goal Name | C14: Your Age | D14: Priority | E14: Today's Cost (₹) | F14: Inflated Cost (₹)
B15: Dream Vacation | C15: 38 | D15: High | E15: =E11 -> 7563998.8 | F15: =IF(C15>0,E15*POWER(1+Profile!C7,MAX(0,C15-Profile!C4)),0) -> 12055865
B16: Business / Startup | C16: 40 | D16: Medium | E16: 2000000 | F16: =IF(C16>0,E16*POWER(1+Profile!C7,MAX(0,C16-Profile!C4)),0) -> 3581695.4
B17: Second Home / Land | C17: 45 | D17: Low | E17: 0 | F17: =IF(C17>0,E17*POWER(1+Profile!C7,MAX(0,C17-Profile!C4)),0) -> 0
B18: Car Upgrade | C18: 35 | D18: Medium | E18: 1000000 | F18: =IF(C18>0,E18*POWER(1+Profile!C7,MAX(0,C18-Profile!C4)),0) -> 1338225.6
B19: Parent Care Fund | C19: 50 | D19: High | E19: 1000000 | F19: =IF(C19>0,E19*POWER(1+Profile!C7,MAX(0,C19-Profile!C4)),0) -> 3207135.5
B20: Custom Goal 1 | C20: 0 | D20: — | E20: 0 | F20: =IF(C20>0,E20*POWER(1+Profile!C7,MAX(0,C20-Profile!C4)),0) -> 0
B21: Custom Goal 2 | C21: 0 | D21: — | E21: 0 | F21: =IF(C21>0,E21*POWER(1+Profile!C7,MAX(0,C21-Profile!C4)),0) -> 0
B22: Custom Goal 3 | C22: 0 | D22: — | E22: 0 | F22: =IF(C22>0,E22*POWER(1+Profile!C7,MAX(0,C22-Profile!C4)),0) -> 0
B23: TOTAL CUSTOM GOALS | E23: =SUM(F15:F22) -> 20182921
B25: 📊 TOTAL LIFE EVENTS IMPACT
B26: Marriage Cost (inflated) | E26: =F5 -> 1685400
B27: Children Education (inflated) | E27: =E11 -> 7563998.8
B28: Custom Goals (inflated) | E28: =E23 -> 20182921
B29: GRAND TOTAL LIFE EVENTS | E29: =E26+E27+E28 -> 29432320
E30: =E29 -> 29432320

Sheet Projections
A1: 📈 WEALTH PROJECTION — Year by Year
A5: Years to Freedom → | B5: =IFERROR(MATCH(TRUE(),INDEX(Projections!E8:E68>=Profile!C30,0),0)-1,">55") -> 33
A6: 📊 ANNUAL WEALTH PROJECTION TABLE
A7: Year | B7: Age | C7: Annual SIP (₹) | D7: Investment Value (₹) | E7: Projected Corpus (₹) | F7: Freedom Number (₹) | G7: Surplus / Gap (₹) | H7: Progress % | I7: Status
A8: 0 | B8: =Profile!C4 -> 30 | C8: =Investments!B36*12 -> 336000 | D8: =Investments!B38 -> 760000 | E8: =D8 -> 760000 | F8: =Profile!C30 -> 74171860 | G8: =E8-F8 -> -73411860 | H8: =IFERROR(E8/F8,0) -> 0.010246474 | I8: =IF(E8>=F8,"🏆 FREE!","Working...") -> Working...
A9: 1 | B9: =Profile!C4+1 -> 31 | C9: =Investments!B36*12 -> 336000 | D9: =D8*(1+IFERROR(Investments!E18,0.1))+C9 -> 1166850 | E9: =D9 -> 1166850 | F9: =Profile!C30 -> 74171860 | G9: =E9-F9 -> -73005010 | H9: =IFERROR(E9/F9,0) -> 0.015731707 | I9: =IF(E9>=F9,"🏆 FREE!","Working...") -> Working...
A10: 2 | B10: =Profile!C4+2 -> 32 | C10: =Investments!B36*12 -> 336000 | D10: =D9*(1+IFERROR(Investments!E18,0.1))+C10 -> 1611628.1 | E10: =D10 -> 1611628.1 | F10: =Profile!C30 -> 74171860 | G10: =E10-F10 -> -72560232 | H10: =IFERROR(E10/F10,0) -> 0.021728295 | I10: =IF(E10>=F10,"🏆 FREE!","Working...") -> Working...
A11: 3 | B11: =Profile!C4+3 -> 33 | C11: =Investments!B36*12 -> 336000 | D11: =D10*(1+IFERROR(Investments!E18,0.1))+C11 -> 2097870 | E11: =D11 -> 2097870 | F11: =Profile!C30 -> 74171860 | G11: =E11-F11 -> -72073990 | H11: =IFERROR(E11/F11,0) -> 0.028283907 | I11: =IF(E11>=F11,"🏆 FREE!","Working...") -> Working...
A12: 4 | B12: =Profile!C4+4 -> 34 | C12: =Investments!B36*12 -> 336000 | D12: =D11*(1+IFERROR(Investments!E18,0.1))+C12 -> 2629441.1 | E12: =D12 -> 2629441.1 | F12: =Profile!C30 -> 74171860 | G12: =E12-F12 -> -71542419 | H12: =IFERROR(E12/F12,0) -> 0.035450657 | I12: =IF(E12>=F12,"🏆 FREE!","Working...") -> Working...
A13: 5 | B13: =Profile!C4+5 -> 35 | C13: =Investments!B36*12 -> 336000 | D13: =D12*(1+IFERROR(Investments!E18,0.1))+C13 -> 3210567.3 | E13: =D13 -> 3210567.3 | F13: =Profile!C30 -> 74171860 | G13: =E13-F13 -> -70961293 | H13: =IFERROR(E13/F13,0) -> 0.043285517 | I13: =IF(E13>=F13,"🏆 FREE!","Working...") -> Working...
A14: 6 | B14: =Profile!C4+6 -> 36 | C14: =Investments!B36*12 -> 336000 | D14: =D13*(1+IFERROR(Investments!E18,0.1))+C14 -> 3845868.2 | E14: =D14 -> 3845868.2 | F14: =Profile!C30 -> 74171860 | G14: =E14-F14 -> -70325992 | H14: =IFERROR(E14/F14,0) -> 0.051850772 | I14: =IF(E14>=F14,"🏆 FREE!","Working...") -> Working...
A15: 7 | B15: =Profile!C4+7 -> 37 | C15: =Investments!B36*12 -> 336000 | D15: =D14*(1+IFERROR(Investments!E18,0.1))+C15 -> 4540394.2 | E15: =D15 -> 4540394.2 | F15: =Profile!C30 -> 74171860 | G15: =E15-F15 -> -69631466 | H15: =IFERROR(E15/F15,0) -> 0.061214512 | I15: =IF(E15>=F15,"🏆 FREE!","Working...") -> Working...
A16: 8 | B16: =Profile!C4+8 -> 38 | C16: =Investments!B36*12 -> 336000 | D16: =D15*(1+IFERROR(Investments!E18,0.1))+C16 -> 5299666.5 | E16: =D16 -> 5299666.5 | F16: =Profile!C30 -> 74171860 | G16: =E16-F16 -> -68872193 | H16: =IFERROR(E16/F16,0) -> 0.071451175 | I16: =IF(E16>=F16,"🏆 FREE!","Working...") -> Working...
A17: 9 | B17: =Profile!C4+9 -> 39 | C17: =Investments!B36*12 -> 336000 | D17: =D16*(1+IFERROR(Investments!E18,0.1))+C17 -> 6129721 | E17: =D17 -> 6129721 | F17: =Profile!C30 -> 74171860 | G17: =E17-F17 -> -68042139 | H17: =IFERROR(E17/F17,0) -> 0.082642136 | I17: =IF(E17>=F17,"🏆 FREE!","Working...") -> Working...
A18: 10 | B18: =Profile!C4+10 -> 40 | C18: =Investments!B36*12 -> 336000 | D18: =D17*(1+IFERROR(Investments!E18,0.1))+C18 -> 7037156.1 | E18: =D18 -> 7037156.1 | F18: =Profile!C30 -> 74171860 | G18: =E18-F18 -> -67134704 | H18: =IFERROR(E18/F18,0) -> 0.094876361 | I18: =IF(E18>=F18,"🏆 FREE!","Working...") -> Working...
A19: 11 | B19: =Profile!C4+11 -> 41 | C19: =Investments!B36*12 -> 336000 | D19: =D18*(1+IFERROR(Investments!E18,0.1))+C19 -> 8029185.7 | E19: =D19 -> 8029185.7 | F19: =Profile!C30 -> 74171860 | G19: =E19-F19 -> -66142674 | H19: =IFERROR(E19/F19,0) -> 0.1082511 | I19: =IF(E19>=F19,"🏆 FREE!","Working...") -> Working...
A20: 12 | B20: =Profile!C4+12 -> 42 | C20: =Investments!B36*12 -> 336000 | D20: =D19*(1+IFERROR(Investments!E18,0.1))+C20 -> 9113696 | E20: =D20 -> 9113696 | F20: =Profile!C30 -> 74171860 | G20: =E20-F20 -> -65058164 | H20: =IFERROR(E20/F20,0) -> 0.12287269 | I20: =IF(E20>=F20,"🏆 FREE!","Working...") -> Working...
A21: 13 | B21: =Profile!C4+13 -> 43 | C21: =Investments!B36*12 -> 336000 | D21: =D20*(1+IFERROR(Investments!E18,0.1))+C21 -> 10299308 | E21: =D21 -> 10299308 | F21: =Profile!C30 -> 74171860 | G21: =E21-F21 -> -63872552 | H21: =IFERROR(E21/F21,0) -> 0.13885736 | I21: =IF(E21>=F21,"🏆 FREE!","Working...") -> Working...
A22: 14 | B22: =Profile!C4+14 -> 44 | C22: =Investments!B36*12 -> 336000 | D22: =D21*(1+IFERROR(Investments!E18,0.1))+C22 -> 11595448 | E22: =D22 -> 11595448 | F22: =Profile!C30 -> 74171860 | G22: =E22-F22 -> -62576412 | H22: =IFERROR(E22/F22,0) -> 0.15633217 | I22: =IF(E22>=F22,"🏆 FREE!","Working...") -> Working...
A23: 15 | B23: =Profile!C4+15 -> 45 | C23: =Investments!B36*12 -> 336000 | D23: =D22*(1+IFERROR(Investments!E18,0.1))+C23 -> 13012418 | E23: =D23 -> 13012418 | F23: =Profile!C30 -> 74171860 | G23: =E23-F23 -> -61159442 | H23: =IFERROR(E23/F23,0) -> 0.17543605 | I23: =IF(E23>=F23,"🏆 FREE!","Working...") -> Working...
A24: 16 | B24: =Profile!C4+16 -> 46 | C24: =Investments!B36*12 -> 336000 | D24: =D23*(1+IFERROR(Investments!E18,0.1))+C24 -> 14561484 | E24: =D24 -> 14561484 | F24: =Profile!C30 -> 74171860 | G24: =E24-F24 -> -59610376 | H24: =IFERROR(E24/F24,0) -> 0.19632087 | I24: =IF(E24>=F24,"🏆 FREE!","Working...") -> Working...
A25: 17 | B25: =Profile!C4+17 -> 47 | C25: =Investments!B36*12 -> 336000 | D25: =D24*(1+IFERROR(Investments!E18,0.1))+C25 -> 16254959 | E25: =D25 -> 16254959 | F25: =Profile!C30 -> 74171860 | G25: =E25-F25 -> -57916901 | H25: =IFERROR(E25/F25,0) -> 0.21915264 | I25: =IF(E25>=F25,"🏆 FREE!","Working...") -> Working...
A26: 18 | B26: =Profile!C4+18 -> 48 | C26: =Investments!B36*12 -> 336000 | D26: =D25*(1+IFERROR(Investments!E18,0.1))+C26 -> 18106306 | E26: =D26 -> 18106306 | F26: =Profile!C30 -> 74171860 | G26: =E26-F26 -> -56065554 | H26: =IFERROR(E26/F26,0) -> 0.24411288 | I26: =IF(E26>=F26,"🏆 FREE!","Working...") -> Working...
A27: 19 | B27: =Profile!C4+19 -> 49 | C27: =Investments!B36*12 -> 336000 | D27: =D26*(1+IFERROR(Investments!E18,0.1))+C27 -> 20130243 | E27: =D27 -> 20130243 | F27: =Profile!C30 -> 74171860 | G27: =E27-F27 -> -54041617 | H27: =IFERROR(E27/F27,0) -> 0.2714 | I27: =IF(E27>=F27,"🏆 FREE!","Working...") -> Working...
A28: 20 | B28: =Profile!C4+20 -> 50 | C28: =Investments!B36*12 -> 336000 | D28: =D27*(1+IFERROR(Investments!E18,0.1))+C28 -> 22342858 | E28: =D28 -> 22342858 | F28: =Profile!C30 -> 74171860 | G28: =E28-F28 -> -51829002 | H28: =IFERROR(E28/F28,0) -> 0.30123093 | I28: =IF(E28>=F28,"🏆 FREE!","Working...") -> Working...
A29: 21 | B29: =Profile!C4+21 -> 51 | C29: =Investments!B36*12 -> 336000 | D29: =D28*(1+IFERROR(Investments!E18,0.1))+C29 -> 24761742 | E29: =D29 -> 24761742 | F29: =Profile!C30 -> 74171860 | G29: =E29-F29 -> -49410118 | H29: =IFERROR(E29/F29,0) -> 0.3338428 | I29: =IF(E29>=F29,"🏆 FREE!","Working...") -> Working...
A30: 22 | B30: =Profile!C4+22 -> 52 | C30: =Investments!B36*12 -> 336000 | D30: =D29*(1+IFERROR(Investments!E18,0.1))+C30 -> 27406122 | E30: =D30 -> 27406122 | F30: =Profile!C30 -> 74171860 | G30: =E30-F30 -> -46765738 | H30: =IFERROR(E30/F30,0) -> 0.36949488 | I30: =IF(E30>=F30,"🏆 FREE!","Working...") -> Working...
A31: 23 | B31: =Profile!C4+23 -> 53 | C31: =Investments!B36*12 -> 336000 | D31: =D30*(1+IFERROR(Investments!E18,0.1))+C31 -> 30297022 | E31: =D31 -> 30297022 | F31: =Profile!C30 -> 74171860 | G31: =E31-F31 -> -43874838 | H31: =IFERROR(E31/F31,0) -> 0.40847057 | I31: =IF(E31>=F31,"🏆 FREE!","Working...") -> Working...
A32: 24 | B32: =Profile!C4+24 -> 54 | C32: =Investments!B36*12 -> 336000 | D32: =D31*(1+IFERROR(Investments!E18,0.1))+C32 -> 33457422 | E32: =D32 -> 33457422 | F32: =Profile!C30 -> 74171860 | G32: =E32-F32 -> -40714438 | H32: =IFERROR(E32/F32,0) -> 0.45107972 | I32: =IF(E32>=F32,"🏆 FREE!","Working...") -> Working...
A33: 25 | B33: =Profile!C4+25 -> 55 | C33: =Investments!B36*12 -> 336000 | D33: =D32*(1+IFERROR(Investments!E18,0.1))+C33 -> 36912446 | E33: =D33 -> 36912446 | F33: =Profile!C30 -> 74171860 | G33: =E33-F33 -> -37259414 | H33: =IFERROR(E33/F33,0) -> 0.49766106 | I33: =IF(E33>=F33,"🏆 FREE!","Working...") -> Working...
A34: 26 | B34: =Profile!C4+26 -> 56 | C34: =Investments!B36*12 -> 336000 | D34: =D33*(1+IFERROR(Investments!E18,0.1))+C34 -> 40689560 | E34: =D34 -> 40689560 | F34: =Profile!C30 -> 74171860 | G34: =E34-F34 -> -33482300 | H34: =IFERROR(E34/F34,0) -> 0.54858487 | I34: =IF(E34>=F34,"🏆 FREE!","Working...") -> Working...
A35: 27 | B35: =Profile!C4+27 -> 57 | C35: =Investments!B36*12 -> 336000 | D35: =D34*(1+IFERROR(Investments!E18,0.1))+C35 -> 44818791 | E35: =D35 -> 44818791 | F35: =Profile!C30 -> 74171860 | G35: =E35-F35 -> -29353069 | H35: =IFERROR(E35/F35,0) -> 0.604256 | I35: =IF(E35>=F35,"🏆 FREE!","Working...") -> Working...
A36: 28 | B36: =Profile!C4+28 -> 58 | C36: =Investments!B36*12 -> 336000 | D36: =D35*(1+IFERROR(Investments!E18,0.1))+C36 -> 49332964 | E36: =D36 -> 49332964 | F36: =Profile!C30 -> 74171860 | G36: =E36-F36 -> -24838896 | H36: =IFERROR(E36/F36,0) -> 0.66511699 | I36: =IF(E36>=F36,"🏆 FREE!","Working...") -> Working...
A37: 29 | B37: =Profile!C4+29 -> 59 | C37: =Investments!B36*12 -> 336000 | D37: =D36*(1+IFERROR(Investments!E18,0.1))+C37 -> 54267965 | E37: =D37 -> 54267965 | F37: =Profile!C30 -> 74171860 | G37: =E37-F37 -> -19903895 | H37: =IFERROR(E37/F37,0) -> 0.73165166 | I37: =IF(E37>=F37,"🏆 FREE!","Working...") -> Working...
A38: 30 | B38: =Profile!C4+30 -> 60 | C38: =Investments!B36*12 -> 336000 | D38: =D37*(1+IFERROR(Investments!E18,0.1))+C38 -> 59663024 | E38: =D38 -> 59663024 | F38: =Profile!C30 -> 74171860 | G38: =E38-F38 -> -14508836 | H38: =IFERROR(E38/F38,0) -> 0.80438895 | I38: =IF(E38>=F38,"🏆 FREE!","Working...") -> Working...
A39: 31 | B39: =Profile!C4+31 -> 61 | C39: =Investments!B36*12 -> 336000 | D39: =D38*(1+IFERROR(Investments!E18,0.1))+C39 -> 65561031 | E39: =D39 -> 65561031 | F39: =Profile!C30 -> 74171860 | G39: =E39-F39 -> -8610828.8 | H39: =IFERROR(E39/F39,0) -> 0.88390707 | I39: =IF(E39>=F39,"🏆 FREE!","Working...") -> Working...
A40: 32 | B40: =Profile!C4+32 -> 62 | C40: =Investments!B36*12 -> 336000 | D40: =D39*(1+IFERROR(Investments!E18,0.1))+C40 -> 72008872 | E40: =D40 -> 72008872 | F40: =Profile!C30 -> 74171860 | G40: =E40-F40 -> -2162988 | H40: =IFERROR(E40/F40,0) -> 0.97083816 | I40: =IF(E40>=F40,"🏆 FREE!","Working...") -> Working...
A41: 33 | B41: =Profile!C4+33 -> 63 | C41: =Investments!B36*12 -> 336000 | D41: =D40*(1+IFERROR(Investments!E18,0.1))+C41 -> 79057804 | E41: =D41 -> 79057804 | F41: =Profile!C30 -> 74171860 | G41: =E41-F41 -> 4885944.4 | H41: =IFERROR(E41/F41,0) -> 1.0658733 | I41: =IF(E41>=F41,"🏆 FREE!","Working...") -> 🏆 FREE!
A42: 34 | B42: =Profile!C4+34 -> 64 | C42: =Investments!B36*12 -> 336000 | D42: =D41*(1+IFERROR(Investments!E18,0.1))+C42 -> 86763864 | E42: =D42 -> 86763864 | F42: =Profile!C30 -> 74171860 | G42: =E42-F42 -> 12592004 | H42: =IFERROR(E42/F42,0) -> 1.1697679 | I42: =IF(E42>=F42,"🏆 FREE!","Working...") -> 🏆 FREE!
A43: 35 | B43: =Profile!C4+35 -> 65 | C43: =Investments!B36*12 -> 336000 | D43: =D42*(1+IFERROR(Investments!E18,0.1))+C43 -> 95188311 | E43: =D43 -> 95188311 | F43: =Profile!C30 -> 74171860 | G43: =E43-F43 -> 21016451 | H43: =IFERROR(E43/F43,0) -> 1.283348 | I43: =IF(E43>=F43,"🏆 FREE!","Working...") -> 🏆 FREE!
...
